<?xml version='1.0' encoding='utf-8'?>
<robot name="base_link">
    <link name="link_1_1">
        <inertial>
            <origin xyz="-0.037949941928318846 -0.09744132570425558 0.03883429888507256" rpy="0.0 0.0 0.0" />
            <mass value="0.36914291072258437" />
            <inertia ixx="0.00016583494987659382" iyy="0.00012963751307110523" izz="0.00018444108683002687" ixy="-3.1348156946775304e-05" iyz="4.360609764316677e-06" ixz="2.517892227090198e-06" />
        </inertial>
        <visual name="link_1_1_visual">
            <origin xyz="0.0 0.0 0.0" rpy="0.0 0.0 0.0" />
            <geometry>
                <mesh filename="meshes/link_1_1.stl" scale="0.001 0.001 0.001" />
            </geometry>
        </visual>
        <collision name="link_1_1_collision">
            <origin xyz="0.0 0.0 0.0" rpy="0.0 0.0 0.0" />
            <geometry>
                <mesh filename="meshes/link_1_1.stl" scale="0.001 0.001 0.001" />
            </geometry>
        </collision>
    </link>
    <link name="link_1_2">
        <inertial>
            <origin xyz="-0.03794994192831925 -0.09744132570425536 0.03883429888507257" rpy="0.0 0.0 0.0" />
            <mass value="0.36914291072258437" />
            <inertia ixx="0.000165834949876606" iyy="0.00012963751307108696" izz="0.00018444108683002188" ixy="-3.134815694675809e-05" iyz="4.36060976431167e-06" ixz="2.5178922270956126e-06" />
        </inertial>
        <visual name="link_1_2_visual">
            <origin xyz="0.0 0.0 0.0" rpy="0.0 0.0 0.0" />
            <geometry>
                <mesh filename="meshes/link_1_2.stl" scale="0.001 0.001 0.001" />
            </geometry>
        </visual>
        <collision name="link_1_2_collision">
            <origin xyz="0.0 0.0 0.0" rpy="0.0 0.0 0.0" />
            <geometry>
                <mesh filename="meshes/link_1_2.stl" scale="0.001 0.001 0.001" />
            </geometry>
        </collision>
    </link>
    <link name="link_1_3">
        <inertial>
            <origin xyz="0.021619002452234692 -0.005792842174673889 -0.025106395945782848" rpy="0.0 -0.0 1.555649252811405e-48" />
            <mass value="0.36914291072258437" />
            <inertia ixx="0.00011638807452707053" iyy="0.00017908438842061548" izz="0.00018444108683003316" ixy="1.8098718402753327e-05" iyz="-1.302998066369694e-06" ixz="4.863835402520942e-06" />
        </inertial>
        <visual name="link_1_3_visual">
            <origin xyz="-0.07411708100420121 0.03627391871546217 0.013727902939290005" rpy="3.1415926535897922 8.743439574056879e-16 -2.3561944901923457" />
            <geometry>
                <mesh filename="meshes/link_1_3.stl" scale="0.001 0.001 0.001" />
            </geometry>
        </visual>
        <collision name="link_1_3_collision">
            <origin xyz="-0.07411708100420121 0.03627391871546217 0.013727902939290005" rpy="3.1415926535897922 8.743439574056879e-16 -2.3561944901923457" />
            <geometry>
                <mesh filename="meshes/link_1_3.stl" scale="0.001 0.001 0.001" />
            </geometry>
        </collision>
    </link>
    <link name="link_1_4">
        <inertial>
            <origin xyz="0.005792745972528533 -0.021619028659459225 -0.023306396190172825" rpy="0.0 -0.0 1.555649252811405e-48" />
            <mass value="0.36914291072258437" />
            <inertia ixx="0.0001790842598599551" iyy="0.00011638820308773352" izz="0.0001844410868300297" ixy="1.809894107635988e-05" iyz="-4.863704051593484e-06" ixz="1.3034882746944467e-06" />
        </inertial>
        <visual name="link_1_4_visual">
            <origin xyz="-0.005644412169905857 0.08232423211770966 0.015527902694900063" rpy="3.1415926535897927 1.713705127796364e-17 2.879793265790644" />
            <geometry>
                <mesh filename="meshes/link_1_4.stl" scale="0.001 0.001 0.001" />
            </geometry>
        </visual>
        <collision name="link_1_4_collision">
            <origin xyz="-0.005644412169905857 0.08232423211770966 0.015527902694900063" rpy="3.1415926535897927 1.713705127796364e-17 2.879793265790644" />
            <geometry>
                <mesh filename="meshes/link_1_4.stl" scale="0.001 0.001 0.001" />
            </geometry>
        </collision>
    </link>
    <link name="link_1_5">
        <inertial>
            <origin xyz="-0.01582624530857041 -0.01582617824322324 -0.02330639619017279" rpy="0.0 -0.0 1.555649252811405e-48" />
            <mass value="0.36914291072258437" />
            <inertia ixx="0.0001477363600344908" iyy="0.0001477361029131822" izz="0.0001844410868300158" ixy="-3.619765947908979e-05" iyz="-3.560705985211833e-06" ixz="-3.56034712782969e-06" />
        </inertial>
        <visual name="link_1_5_visual">
            <origin xyz="0.06847268000543122 0.04605032164380951 0.015527902694899974" rpy="-3.141592653589793 -1.508082362978311e-16 1.8325957145940424" />
            <geometry>
                <mesh filename="meshes/link_1_5.stl" scale="0.001 0.001 0.001" />
            </geometry>
        </visual>
        <collision name="link_1_5_collision">
            <origin xyz="0.06847268000543122 0.04605032164380951 0.015527902694899974" rpy="-3.141592653589793 -1.508082362978311e-16 1.8325957145940424" />
            <geometry>
                <mesh filename="meshes/link_1_5.stl" scale="0.001 0.001 0.001" />
            </geometry>
        </collision>
    </link>
    <link name="link_1_6">
        <inertial>
            <origin xyz="-0.03794994192831883 -0.09744132570425497 0.0388342988850727" rpy="0.0 0.0 0.0" />
            <mass value="0.36914291072258437" />
            <inertia ixx="0.00016583494987660035" iyy="0.000129637513071093" izz="0.00018444108683004687" ixy="-3.1348156946773935e-05" iyz="4.360609764312606e-06" ixz="2.517892227083385e-06" />
        </inertial>
        <visual name="link_1_6_visual">
            <origin xyz="0.0 0.0 0.0" rpy="0.0 0.0 0.0" />
            <geometry>
                <mesh filename="meshes/link_1_6.stl" scale="0.001 0.001 0.001" />
            </geometry>
        </visual>
        <collision name="link_1_6_collision">
            <origin xyz="0.0 0.0 0.0" rpy="0.0 0.0 0.0" />
            <geometry>
                <mesh filename="meshes/link_1_6.stl" scale="0.001 0.001 0.001" />
            </geometry>
        </collision>
    </link>
    <link name="link_2_1">
        <inertial>
            <origin xyz="0.03956033205668474 -0.0026359793082563333 -0.037825768790633305" rpy="0.0 8.511212647632786e-31 0.0" />
            <mass value="0.5870673755794086" />
            <inertia ixx="0.0002049978562715309" iyy="0.0008928463308917646" izz="0.0007745880375809385" ixy="6.572602663475909e-07" iyz="2.4549193540669483e-06" ixz="0.00016446227358901872" />
        </inertial>
        <visual name="link_2_1_visual">
            <origin xyz="-0.011987563322325397 0.11295848811353337 -0.030373601714721886" rpy="-1.5707963267949019 -1.308996938995788 -3.1415926535897927" />
            <geometry>
                <mesh filename="meshes/link_2_1.stl" scale="0.001 0.001 0.001" />
            </geometry>
        </visual>
        <collision name="link_2_1_collision">
            <origin xyz="-0.011987563322325397 0.11295848811353337 -0.030373601714721886" rpy="-1.5707963267949019 -1.308996938995788 -3.1415926535897927" />
            <geometry>
                <mesh filename="meshes/link_2_1.stl" scale="0.001 0.001 0.001" />
            </geometry>
        </collision>
    </link>
    <link name="link_2_2">
        <inertial>
            <origin xyz="0.04412068851487504 -0.0026359830470657464 0.0323909480065781" rpy="0.0 -8.511212647632786e-31 0.0" />
            <mass value="0.5870673755794086" />
            <inertia ixx="0.0007011633816659796" iyy="0.0008928463308917924" izz="0.00027842251218654715" ixy="-2.303491565378635e-06" iyz="1.07356727821409e-06" ixz="-0.0002519496426134247" />
        </inertial>
        <visual name="link_2_2_visual">
            <origin xyz="0.02783053850664504 0.11295848437472404 -0.017079763781731643" rpy="-1.5707963267948981 0.08726646259968006 3.141592653589792" />
            <geometry>
                <mesh filename="meshes/link_2_2.stl" scale="0.001 0.001 0.001" />
            </geometry>
        </visual>
        <collision name="link_2_2_collision">
            <origin xyz="0.02783053850664504 0.11295848437472404 -0.017079763781731643" rpy="-1.5707963267948981 0.08726646259968006 3.141592653589792" />
            <geometry>
                <mesh filename="meshes/link_2_2.stl" scale="0.001 0.001 0.001" />
            </geometry>
        </collision>
    </link>
    <link name="link_2_3">
        <inertial>
            <origin xyz="-0.01534737214980069 -0.002635983047065693 0.05253824379099852" rpy="9.860761315262648e-32 5.5511151231256977e-17 -3.944304526105059e-31" />
            <mass value="0.5870673755794086" />
            <inertia ixx="0.0004898239084911135" iyy="0.0008928463308917824" izz="0.0004897619853613377" ixy="-1.7966637645751188e-06" iyz="-1.7973923916713797e-06" ixz="0.0003288709201745909" />
        </inertial>
        <visual name="link_2_3_visual">
            <origin xyz="0.025568331222089232 0.1129584843747239 0.020310530100508685" rpy="-1.570796326794902 1.3089969389957083 3.1415926535897896" />
            <geometry>
                <mesh filename="meshes/link_2_3.stl" scale="0.001 0.001 0.001" />
            </geometry>
        </visual>
        <collision name="link_2_3_collision">
            <origin xyz="0.025568331222089232 0.1129584843747239 0.020310530100508685" rpy="-1.570796326794902 1.3089969389957083 3.1415926535897896" />
            <geometry>
                <mesh filename="meshes/link_2_3.stl" scale="0.001 0.001 0.001" />
            </geometry>
        </collision>
    </link>
    <link name="link_2_4">
        <inertial>
            <origin xyz="-0.03955573957224152 0.0026359832914551974 0.03782453415871988" rpy="0.0 8.511212647632786e-31 1.9721522630525295e-31" />
            <mass value="0.5870673755794086" />
            <inertia ixx="0.00020496689470663582" iyy="0.000892846330891806" izz="0.000774618999145857" ixy="6.582555894586825e-07" iyz="2.4546526580410586e-06" ixz="0.00016440864658557415" />
        </inertial>
        <visual name="link_2_4_visual">
            <origin xyz="-0.08792361002004169 -0.11295848413033499 0.057144715847239756" rpy="1.5707963267948915 0.7853981633974828 -3.1415926535897927" />
            <geometry>
                <mesh filename="meshes/link_2_4.stl" scale="0.001 0.001 0.001" />
            </geometry>
        </visual>
        <collision name="link_2_4_collision">
            <origin xyz="-0.08792361002004169 -0.11295848413033499 0.057144715847239756" rpy="1.5707963267948915 0.7853981633974828 -3.1415926535897927" />
            <geometry>
                <mesh filename="meshes/link_2_4.stl" scale="0.001 0.001 0.001" />
            </geometry>
        </collision>
    </link>
    <link name="link_2_5">
        <inertial>
            <origin xyz="0.012979141854366034 0.002635983291455144 0.05316854851910561" rpy="0.0 8.511212647632782e-31 1.9721522630525295e-31" />
            <mass value="0.5870673755794086" />
            <inertia ixx="0.0007745880375809777" iyy="0.000892846330891806" izz="0.00020499785627153152" ixy="2.454919354046034e-06" iyz="6.572602663671868e-07" ixz="0.00016446227358898988" />
        </inertial>
        <visual name="link_2_5_visual">
            <origin xyz="0.0055269747784553935 -0.11295848413033494 0.10471644389811526" rpy="1.570796326794891 -0.2617993877991173 -3.141592653589791" />
            <geometry>
                <mesh filename="meshes/link_2_5.stl" scale="0.001 0.001 0.001" />
            </geometry>
        </visual>
        <collision name="link_2_5_collision">
            <origin xyz="0.0055269747784553935 -0.11295848413033494 0.10471644389811526" rpy="1.570796326794891 -0.2617993877991173 -3.141592653589791" />
            <geometry>
                <mesh filename="meshes/link_2_5.stl" scale="0.001 0.001 0.001" />
            </geometry>
        </collision>
    </link>
    <link name="link_2_6">
        <inertial>
            <origin xyz="0.05253823799732768 -0.0026359793082563867 0.015347372904517336" rpy="0.0 8.511212647632786e-31 1.9721522630525295e-31" />
            <mass value="0.5870673755794086" />
            <inertia ixx="0.0004897619853613817" iyy="0.000892846330891813" izz="0.0004898239084911147" ixy="-1.7973923916920015e-06" iyz="1.7966637646044952e-06" ixz="-0.00032887092017463217" />
        </inertial>
        <visual name="link_2_6_visual">
            <origin xyz="0.020310524306837347 0.11295848811353375 -0.025568330467371662" rpy="-1.5707963267949012 -0.2617993877991926 -3.1415926535897922" />
            <geometry>
                <mesh filename="meshes/link_2_6.stl" scale="0.001 0.001 0.001" />
            </geometry>
        </visual>
        <collision name="link_2_6_collision">
            <origin xyz="0.020310524306837347 0.11295848811353375 -0.025568330467371662" rpy="-1.5707963267949012 -0.2617993877991926 -3.1415926535897922" />
            <geometry>
                <mesh filename="meshes/link_2_6.stl" scale="0.001 0.001 0.001" />
            </geometry>
        </collision>
    </link>
    <link name="link_3_1">
        <inertial>
            <origin xyz="0.06853528018735762 0.005084938941100754 -0.04720409525089698" rpy="0.0 1.2890988334177766e-30 0.0" />
            <mass value="1.0486562054964048" />
            <inertia ixx="0.0005905740206741282" iyy="0.002729452593835599" izz="0.0022871203346311766" ixy="0.00020547467588970537" iyz="-5.5925273058158886e-05" ixz="0.00047479762826372745" />
        </inertial>
        <visual name="link_3_1_visual">
            <origin xyz="0.05365652914883846 -0.004296821832915176 -0.0533036040326151" rpy="-1.3099485067468397 -0.022559479597568707 1.6551035730063135" />
            <geometry>
                <mesh filename="meshes/link_3_1.stl" scale="0.001 0.001 0.001" />
            </geometry>
        </visual>
        <collision name="link_3_1_collision">
            <origin xyz="0.05365652914883846 -0.004296821832915176 -0.0533036040326151" rpy="-1.3099485067468397 -0.022559479597568707 1.6551035730063135" />
            <geometry>
                <mesh filename="meshes/link_3_1.stl" scale="0.001 0.001 0.001" />
            </geometry>
        </collision>
    </link>
    <link name="link_3_2">
        <inertial>
            <origin xyz="0.007954372513687122 -0.0017689299956049175 -0.08297449419789463" rpy="0.0 5.551115123125912e-17 -1.9721522630525295e-31" />
            <mass value="1.0486562054964048" />
            <inertia ixx="0.0020633886341791313" iyy="0.0026752873731962926" izz="0.0008684709417654537" ixy="0.00017191759264039187" iyz="-0.0003679853286525651" ixz="0.0007322070781963264" />
        </inertial>
        <visual name="link_3_2_visual">
            <origin xyz="-0.006606989475015795 -0.009999998130594837 -0.07480045422634657" rpy="-0.43633231299858094 -1.908235877051454e-16 1.5707963267948997" />
            <geometry>
                <mesh filename="meshes/link_3_2.stl" scale="0.001 0.001 0.001" />
            </geometry>
        </visual>
        <collision name="link_3_2_collision">
            <origin xyz="-0.006606989475015795 -0.009999998130594837 -0.07480045422634657" rpy="-0.43633231299858094 -1.908235877051454e-16 1.5707963267948997" />
            <geometry>
                <mesh filename="meshes/link_3_2.stl" scale="0.001 0.001 0.001" />
            </geometry>
        </collision>
    </link>
    <link name="link_3_3">
        <inertial>
            <origin xyz="-0.07524996563283722 0.001768929995604136 0.035853613450253445" rpy="0.0 -1.2890988334177761e-30 0.0" />
            <mass value="1.0486562054964048" />
            <inertia ixx="0.001478903396432651" iyy="0.0026752873731963325" izz="0.0014529561795119576" ixy="0.0002869938182172228" iyz="-0.00028740808803495694" ixz="0.0009449423071040545" />
        </inertial>
        <visual name="link_3_3_visual">
            <origin xyz="-0.07254915970395776 0.009999998130593673 0.019374722718258006" rpy="-2.3561944901923417 -2.495654062637968e-14 -1.5707963267948746" />
            <geometry>
                <mesh filename="meshes/link_3_3.stl" scale="0.001 0.001 0.001" />
            </geometry>
        </visual>
        <collision name="link_3_3_collision">
            <origin xyz="-0.07254915970395776 0.009999998130593673 0.019374722718258006" rpy="-2.3561944901923417 -2.495654062637968e-14 -1.5707963267948746" />
            <geometry>
                <mesh filename="meshes/link_3_3.stl" scale="0.001 0.001 0.001" />
            </geometry>
        </collision>
    </link>
    <link name="link_3_4">
        <inertial>
            <origin xyz="-0.06867512606227553 -0.001768929751215964 0.047241575440221804" rpy="0.0 1.2890988334177709e-30 0.0" />
            <mass value="1.0486562054964048" />
            <inertia ixx="0.000641098940679343" iyy="0.002675287373196303" izz="0.002290760635265266" ixy="-0.0003923996146000047" iyz="0.00010483989328774114" ixz="0.0004612356790466058" />
        </inertial>
        <visual name="link_3_4_visual">
            <origin xyz="-0.053053585097739886 -0.00999999788620583 0.053142054261117906" rpy="1.8325957145940552 -2.9568692725328292e-15 1.5707963267949006" />
            <geometry>
                <mesh filename="meshes/link_3_4.stl" scale="0.001 0.001 0.001" />
            </geometry>
        </visual>
        <collision name="link_3_4_collision">
            <origin xyz="-0.053053585097739886 -0.00999999788620583 0.053142054261117906" rpy="1.8325957145940552 -2.9568692725328292e-15 1.5707963267949006" />
            <geometry>
                <mesh filename="meshes/link_3_4.stl" scale="0.001 0.001 0.001" />
            </geometry>
        </collision>
    </link>
    <link name="link_3_6">
        <inertial>
            <origin xyz="0.07524995884726099 -0.0017689299956044292 0.03585361906156397" rpy="0.0 5.551115123125912e-17 -1.9721522630525295e-31" />
            <mass value="1.0486562054964048" />
            <inertia ixx="0.0014789033964326473" iyy="0.0026752873731963334" izz="0.001452956179511984" ixy="0.00028699381821721244" iyz="0.0002874080880349572" ixz="-0.0009449423071040662" />
        </inertial>
        <visual name="link_3_6_visual">
            <origin xyz="0.07254915291838149 -0.00999999813059386 0.0193747283295685" rpy="-2.3561944901923337 -3.469374102921409e-14 1.5707963267949303" />
            <geometry>
                <mesh filename="meshes/link_3_6.stl" scale="0.001 0.001 0.001" />
            </geometry>
        </visual>
        <collision name="link_3_6_collision">
            <origin xyz="0.07254915291838149 -0.00999999813059386 0.0193747283295685" rpy="-2.3561944901923337 -3.469374102921409e-14 1.5707963267949303" />
            <geometry>
                <mesh filename="meshes/link_3_6.stl" scale="0.001 0.001 0.001" />
            </geometry>
        </collision>
    </link>
    <link name="link_3_5">
        <inertial>
            <origin xyz="0.006574838553662783 -0.0017689297512162839 0.08309518097654323" rpy="0.0 1.2890988334177693e-30 -1.9721522630525295e-31" />
            <mass value="1.0486562054964048" />
            <inertia ixx="0.002277787026804913" iyy="0.002675287373196277" izz="0.000654072549139687" ixy="-0.00010540579638277364" iyz="0.0003922479813226898" ixz="0.0004837066280574539" />
        </inertial>
        <visual name="link_3_5_visual">
            <origin xyz="0.019495573589318714 -0.009999997886206122 0.07251676906544414" rpy="2.8797932657906498 -3.814369767060013e-15 1.5707963267948997" />
            <geometry>
                <mesh filename="meshes/link_3_5.stl" scale="0.001 0.001 0.001" />
            </geometry>
        </visual>
        <collision name="link_3_5_collision">
            <origin xyz="0.019495573589318714 -0.009999997886206122 0.07251676906544414" rpy="2.8797932657906498 -3.814369767060013e-15 1.5707963267948997" />
            <geometry>
                <mesh filename="meshes/link_3_5.stl" scale="0.001 0.001 0.001" />
            </geometry>
        </collision>
    </link>
    <link name="base_link">
        <inertial>
            <origin xyz="0.023017229120898014 -0.08464530203925047 0.0008889846005406454" rpy="0.0 -0.0 1.3564505168326057e-48" />
            <mass value="1.2443830690052136" />
            <inertia ixx="0.0023689215025013517" iyy="0.002416594595253303" izz="0.004668882923273096" ixy="2.5477598085071404e-05" iyz="-2.859342323275442e-07" ixz="-1.8427596792821278e-07" />
        </inertial>
        <visual name="base_link_visual">
            <origin xyz="-0.008480072630274811 -0.04316549971809861 0.03575910067995018" rpy="-3.1415926535897927 -7.894789857880728e-17 -0.2617993877991491" />
            <geometry>
                <mesh filename="meshes/base_link.stl" scale="0.001 0.001 0.001" />
            </geometry>
        </visual>
        <collision name="base_link_collision">
            <origin xyz="-0.008480072630274811 -0.04316549971809861 0.03575910067995018" rpy="-3.1415926535897927 -7.894789857880728e-17 -0.2617993877991491" />
            <geometry>
                <mesh filename="meshes/base_link.stl" scale="0.001 0.001 0.001" />
            </geometry>
        </collision>
    </link>
    <joint name="link_1_1_Revolute-8" type="continuous">
        <origin xyz="-0.0765160172543739 -0.11283961992455112 0.040027742939290054" rpy="1.5707963267948957 1.4079464166806748e-15 -2.3561944901923053" />
        <parent link="link_1_1" />
        <child link="link_2_1" />
        <axis xyz="0.25881917101787577 -3.6286205642770267e-16 0.9659259541758984" />
    </joint>
    <joint name="link_1_2_Revolute-9" type="continuous">
        <origin xyz="-0.03200230519539676 -0.13853962205634698 0.04002774293929005" rpy="-1.5707963267948977 1.301858417446164e-15 3.054326190990116" />
        <parent link="link_1_2" />
        <child link="link_2_2" />
        <axis xyz="-0.906307387001046 8.041487173568244e-16 0.4226184415608677" />
    </joint>
    <joint name="link_1_3_Revolute-10" type="continuous">
        <origin xyz="0.046474270000000005 -0.03905933999999997 -0.026299840000000047" rpy="1.5707963267948954 -2.037995604249017e-15 2.0943951023931544" />
        <parent link="link_1_3" />
        <child link="link_2_3" />
        <axis xyz="-0.7071069541759167 1.3542201102584627e-15 -0.7071068289820557" />
    </joint>
    <joint name="link_1_4_Revolute-11" type="continuous">
        <origin xyz="0.03905933999999999 -0.04647428 -0.02449984000000006" rpy="-1.570796326794898 -2.0379956042490166e-15 2.0943951023931544" />
        <parent link="link_1_4" />
        <child link="link_2_4" />
        <axis xyz="-0.25881917101787566 3.6286205642770267e-16 -0.9659259541758984" />
    </joint>
    <joint name="link_1_5_Revolute-12" type="continuous">
        <origin xyz="-0.020718220000000002 -0.057063519999999965 -0.024499840000000068" rpy="-1.570796326794898 -2.0379956042490166e-15 2.0943951023931544" />
        <parent link="link_1_5" />
        <child link="link_2_5" />
        <axis xyz="-0.9659261251937925 -9.913580538307604e-16 -0.25881912519384276" />
    </joint>
    <joint name="link_1_6_Revolute-13" type="continuous">
        <origin xyz="-0.07651601143787069 -0.11283962325395576 0.040027742939290116" rpy="1.5707963267948952 2.180863290233574e-15 -1.3089969389957075" />
        <parent link="link_1_6" />
        <child link="link_2_6" />
        <axis xyz="-0.7071069541759167 -1.3542201102584627e-15 0.7071068289820557" />
    </joint>
    <joint name="link_2_1_Revolute-14" type="continuous">
        <origin xyz="0.0927288757444798 1.3322676295501878e-16 -0.024846635881817694" rpy="-1.6171016581961693e-16 -5.38458166943201e-15 -2.800902232999916e-16" />
        <parent link="link_2_1" />
        <child link="link_3_1" />
        <axis xyz="-0.2588191710178809 4.465693832422435e-16 -0.9659259541758967" />
    </joint>
    <joint name="link_2_2_Revolute-15" type="continuous">
        <origin xyz="0.08679305683970955 -1.509903313490213e-16 0.06545201580941072" rpy="3.141592653589793 5.3290705182007506e-15 2.800902232999909e-16" />
        <parent link="link_2_2" />
        <child link="link_3_2" />
        <axis xyz="0.9063073870010482 9.896548574971433e-16 0.42261844156086287" />
    </joint>
    <joint name="link_2_3_Revolute-16" type="continuous">
        <origin xyz="-0.03167838136385329 -3.552713678800501e-17 0.10408612602374576" rpy="-1.617101658196172e-16 5.440092820663266e-15 2.800902232999903e-16" />
        <parent link="link_2_3" />
        <child link="link_3_3" />
        <axis xyz="-0.7071069541759127 1.6666202175174439e-15 -0.7071068289820595" />
    </joint>
    <joint name="link_2_4_Revolute-17" type="continuous">
        <origin xyz="-0.09272887208422569 -1.2434497875801754e-16 0.02484662222156365" rpy="-1.617101658196172e-16 -1.5543122344752182e-15 -2.800902232999913e-16" />
        <parent link="link_2_4" />
        <child link="link_3_4" />
        <axis xyz="0.2588191710178771 -4.465693832422437e-16 0.9659259541758979" />
    </joint>
    <joint name="link_2_5_Revolute-18" type="continuous">
        <origin xyz="-0.024846622966050037 -8.881784197001253e-17 0.09272888662629919" rpy="-1.61710165819617e-16 -1.5543122344752182e-15 -2.800902232999905e-16" />
        <parent link="link_2_5" />
        <child link="link_3_5" />
        <axis xyz="0.965926125193793 1.2200508342752011e-15 0.25881912519384126" />
    </joint>
    <joint name="link_2_6_Revolute-19" type="continuous">
        <origin xyz="0.06788225277842976 3.552713678800501e-17 0.06788225074448154" rpy="-1.617101658196169e-16 -5.3845816694320084e-15 -2.800902232999907e-16" />
        <parent link="link_2_6" />
        <child link="link_3_6" />
        <axis xyz="0.7071069541759128 1.6666202175174439e-15 -0.7071068289820595" />
    </joint>
    <joint name="link_1_1_Revolute-21" type="continuous">
        <origin xyz="-0.026759156148073143 -0.07805822594294494 0.013727902939289969" rpy="-3.141592653589793 2.0145111903844072e-16 -0.2617993877991487" />
        <parent link="link_1_1" />
        <child link="base_link" />
        <axis xyz="-1.232595164407831e-32 -1.1004833995793566e-16 1.0" />
    </joint>
    <joint name="link_1_6_Revolute-22" type="continuous">
        <origin xyz="-0.02675916291640517 -0.07805822155571397 0.013727902939290017" rpy="-3.1415926535897922 9.454103857724648e-17 0.7853981633974471" />
        <parent link="link_1_6" />
        <child link="base_link" />
        <axis xyz="0.0 -1.1004833995793554e-16 0.9999999999999999" />
    </joint>
    <joint name="link_1_2_Revolute-23" type="continuous">
        <origin xyz="-0.026759155629893165 -0.07805822540560504 0.013727902939289965" rpy="-3.141592653589793 2.1987006485789595e-16 -1.1344640137963145" />
        <parent link="link_1_2" />
        <child link="base_link" />
        <axis xyz="-2.465190328815662e-32 -1.100483399579357e-16 1.0" />
    </joint>
    <joint name="base_link_Revolute-24" type="continuous">
        <origin xyz="0.10777754 -0.10777755000000001 -8.881784197001253e-18" rpy="-8.4123471043246085e-16 1.5380406665155265e-32 -2.7755575615629234e-17" />
        <parent link="base_link" />
        <child link="link_1_3" />
        <axis xyz="-2.465190328815662e-32 -9.512830503903964e-16 0.9999999999999999" />
    </joint>
    <joint name="base_link_Revolute-25" type="continuous">
        <origin xyz="0.045552149999999986 -0.17000294000000002 -1.7763568394002505e-17" rpy="-8.4123471043246085e-16 1.5380406665155265e-32 -2.7755575615629234e-17" />
        <parent link="base_link" />
        <child link="link_1_4" />
        <axis xyz="-2.465190328815662e-32 -9.512830503903964e-16 0.9999999999999999" />
    </joint>
    <joint name="base_link_Revolute-26" type="continuous">
        <origin xyz="-0.03944933000000001 -0.14722687 -1.7763568394002505e-17" rpy="-8.4123471043246085e-16 1.5380406665155265e-32 -2.7755575615629234e-17" />
        <parent link="base_link" />
        <child link="link_1_5" />
        <axis xyz="-2.465190328815662e-32 -9.512830503903964e-16 0.9999999999999999" />
    </joint>
</robot>